Workbook

Sheet Presupuesto Oficial AENA
A1: HAM ESTRUCTURAS METÁLICAS
A2: Estudio Técnico y Presupuesto Oficial · Rehabilitación Cubierta Nave Operativa AENA (Lado Aire)
A4: Cliente: | B4: AENA · Aeropuerto de Menorca (Maó) | E4: Referencia: | F4: ANT-2026-0831-AENA
A5: Emplazamiento: | B5: Nave Lado Aire (Zona Restringida) | E5: Fecha: | F5: 31/08/2026
A6: Plazo de Ejecución: | B6: 3 meses (12 semanas) | E6: Validez Oferta: | F6: 30 días naturales
A8: CÓDIGO | B8: DESCRIPCIÓN DE LA UNIDAD DE OBRA | C8: UD. | D8: CANTIDAD | E8: PRECIO UNITARIO | F8: IMPORTE TOTAL
A9: CAPÍTULO 01 · TRABAJOS PREVIOS, SEGURIDAD Y TRAMITACIÓN LADO AIRE (AENA - 3 MESES)
A10: 01.01 | B10: Tramitación de acreditaciones de seguridad AENA, cursos AVSEC de operarios, autorizaciones de vehículos y maquinaria especial para acceso a plataforma y Lado Aire (cobertura 3 meses de obra). | C10: PA | D10: 1 | E10: 4200 | F10: =D10*E10
A11: 01.02 | B11: Suministro, montaje y posterior desmontaje de redes de seguridad anticaídas bajo cubierta fijadas a correas metálicas, para protección colectiva continua de operarios durante los 3 meses. | C11: m² | D11: 1950 | E11: 4.2 | F11: =D11*E11
A12: 01.03 | B12: Balizamiento perimetral en zona de maniobra, control continuo de residuos ligeros volátiles (protocolo FOD) y líneas de anclaje provisionales de montaje para 3 meses. | C12: PA | D12: 1 | E12: 3000 | F12: =D12*E12
A13: SUBTOTAL CAPÍTULO 01: | F13: =SUM(F10:F12)
A15: CAPÍTULO 02 · DESMONTAJE Y GESTIÓN INTEGRAL DE RESIDUOS CONTAMINADOS
A16: 02.01 | B16: Desmontaje manual y mecánico de cubierta dañada existente (panel sándwich y placas translúcidas), desatornillado ordenado y acopio en cubierta. | C16: m² | D16: 1950 | E16: 7.8 | F16: =D16*E16
A17: 02.02 | B17: Desmontaje de chapas de petos exteriores, panel de peto interior, rematería y canalones viejos deteriorados. | C17: m² | D17: 794.88 | E17: 6.5 | F17: =D17*E17
A18: 02.03 | B18: Bajada controlada de material retirado desde cubierta a cota cero mediante camión grúa / manipulador telescópico homologado. | C18: h | D18: 72 | E18: 95 | F18: =D18*E18
A19: 02.04 | B19: Gestión integral de residuos contaminados: carga mecánica, alquiler de contenedores estancos homologados para Lado Aire durante los 3 meses, transporte autorizado a planta insular de transferencia y canon oficial de vertedero homologado para residuo contaminado de panel sándwich con espuma aislante rígida PUR/PIR, policarbonatos, chapas y petos degradados. | C19: m² | D19: 2744.88 | E19: 8.8 | F19: =D19*E19
A20: SUBTOTAL CAPÍTULO 02: | F20: =SUM(F16:F19)
A22: CAPÍTULO 03 · SUMINISTRO E INSTALACIÓN DE NUEVA CUBIERTA Y LUCERNARIOS
A23: 03.01 | B23: Panel sándwich de cubierta de 50 mm de espesor, chapa exterior grecada lacada con recubrimiento especial marino, núcleo rígido aislante PIR/PUR y chapa interior blanco pirineo. Incluye flete marítimo a Menorca. | C23: m² | D23: 1755 | E23: 55 | F23: =D23*E23
A24: 03.02 | B24: Lucernarios de policarbonato celular grecado de 30-40 mm con protección UV en masa, perfectamente compatibles con la greca del panel para iluminación natural (10% de faldones). | C24: m² | D24: 195 | E24: 48 | F24: =D24*E24
A25: 03.03 | B25: Tornillería autotaladrante reforzada con arandela vulcanizada EPDM y caballetes de fijación para óptimo reparto de presiones de viento. | C25: Ud. | D25: 7500 | E25: 0.38 | F25: =D25*E25
A26: 03.04 | B26: Mano de obra especializada de colocación de cubierta y lucernarios, solapes, fijación reforzada a correas y sellado estanco longitudinal y transversal con butilo. | C26: m² | D26: 1950 | E26: 65.3 | F26: =D26*E26
A27: SUBTOTAL CAPÍTULO 03: | F27: =SUM(F23:F26)
A29: CAPÍTULO 04 · PETOS PERIMETRALES (CHAPA HDX Y PANEL FACHADA) Y REMATERÍA
A30: 04.01 | B30: Chapa prelacada blanca Granite HDX 55 µm (alta resistencia marina C5-M, e=0,6-0,8 mm conformada) para revestimiento exterior de peto superior e inferior (184 ml x 1,2 m x 2). | C30: m² | D30: 529.92 | E30: 38 | F30: =D30*E30
A31: 04.02 | B31: Panel sándwich de fachada de 50 mm cara interior de peto, chapa microperfilada blanca y núcleo rígido aislante térmico PIR/PUR (184 ml x 1,2 m). | C31: m² | D31: 264.96 | E31: 55 | F31: =D31*E31
A32: 04.03 | B32: Mano de obra de montaje de chapas HDX y panel sándwich de fachada en petos perimetrales. | C32: m² | D32: 794.88 | E32: 12.5 | F32: =D32*E32
A33: 04.04 | B33: Rematería conformada en chapa HDX: cumbrera troquelada (70 ml), albardillas de coronación con goterón (184 ml), esquineros y baberos peto-cubierta (184 ml). | C33: ml | D33: 525.6 | E33: 16.5 | F33: =D33*E33
A34: 04.05 | B34: Mano de obra de colocación de rematería perimetral y sellados de estanqueidad con polímero MS. | C34: ml | D34: 525.6 | E34: 8 | F34: =D34*E34
A35: SUBTOTAL CAPÍTULO 04: | F35: =SUM(F30:F34)
A37: CAPÍTULO 05 · CANALONES HDX, BAJANTES Y BABEROS DE ENTREGA
A38: 05.01 | B38: Canalón continuo conformado en chapa Granite HDX (desarrollo 450-500 mm, calidad marina C5-M) para ambos aleros (2 x 70 ml) con baberos HDX, ganchos de pletina cada 60 cm, bajantes exteriores y sellados estancos. | C38: ml | D38: 168 | E38: 81.03 | F38: =D38*E38
A39: SUBTOTAL CAPÍTULO 05: | F39: =SUM(F38:F38)
A41: CAPÍTULO 06 · SISTEMA DE LÍNEA DE VIDA LUX-TOP (EN 795 CLASE C)
A42: 06.01 | B42: Sistema de línea de vida horizontal continua LUX-TOP (normas UNE-EN 795 Clase C y CEN/TS 16415 para uso multiusuario) en acero inoxidable AISI 316 Ø8 mm de 70 ml en cumbrera. Incluye postes extremos e intermedios fijados a estructura con absorbedores dinámicos, kit de tensión con indicador de carga, 2 carros lanzadera de paso continuo, fijaciones reforzadas, pruebas de tiro, verificación y Certificado de Homologación oficial visado. | C42: ml | D42: 84 | E42: 120 | F42: =D42*E42
A43: SUBTOTAL CAPÍTULO 06: | F43: =SUM(F42:F42)
A45: CAPÍTULO 07 · ESCALERA DE GATO INOX CON PROTECCIÓN DORSAL PARA MANTENIMIENTO (12 ML)
A46: 07.01 | B46: Escalera fija vertical de gato en acero inoxidable AISI 316 de 12,00 m de altura según norma UNE-EN ISO 14122-4. Incluye jaula dorsal (crinolina inox), peldaños antideslizantes, rellano intermedio abatible, desembarco superior a cubierta con barandilla y portilla de cierre automático, y chapa inferior abatible con candado de bloqueo de acceso antiasalto para lado aire. | C46: ml | D46: 14.4 | E46: 325 | F46: =D46*E46
A47: 07.02 | B47: Mano de obra especializada de montaje, izado con plataforma elevadora, anclaje y fijación estructural reforzada con tornillería inox A4. | C47: ml | D47: 14.4 | E47: 99.17 | F47: =D47*E47
A48: SUBTOTAL CAPÍTULO 07: | F48: =SUM(F46:F47)
...

Sheet Estudio Costes y Escandallo
A1: ESTUDIO TÉCNICO, ESCANDALLO Y CONTROL DE MARGEN (+20%)
A2: Desglose entre Mediciones Base de Obra, Factor de Incremento en Unidades y Precios Unitarios
A4: PARÁMETRO INCREMENTO EXTRA (UNIDADES): | B4: 0.2 | C4: (Modificable en celda B4: recalcula todas las partidas)
A6: CÓDIGO | B6: CONCEPTO / DESCRIPCIÓN TÉCNICA | C6: UD. | D6: CANTIDAD BASE | E6: EXTRA % | F6: CANTIDAD PRESUP. | G6: PRECIO UNIT. | H6: IMPORTE TOTAL
A7: CAPÍTULO 01 · TRABAJOS PREVIOS, SEGURIDAD Y TRAMITACIÓN LADO AIRE
A8: 01.01 | B8: Tramitación acreditaciones AENA, cursos AVSEC y permisos maquinaria (3 meses) | C8: PA | D8: 1 | E8: 0 | F8: =D8*(1+E8) | G8: 4200 | H8: =F8*G8
A9: 01.02 | B9: Instalación de redes de seguridad anticaídas bajo cubierta (3 meses) | C9: m² | D9: 1625 | E9: =+$B$4 | F9: =D9*(1+E9) | G9: 4.2 | H9: =F9*G9
A10: 01.03 | B10: Balizamiento perimetral continuo, control FOD y líneas de vida provisionales | C10: PA | D10: 1 | E10: 0 | F10: =D10*(1+E10) | G10: 3000 | H10: =F10*G10
A11: SUBTOTAL CAPÍTULO 01: | H11: =SUM(H8:H10)
A13: CAPÍTULO 02 · DESMONTAJE Y GESTIÓN INTEGRAL DE RESIDUOS CONTAMINADOS
A14: 02.01 | B14: Desmontaje manual y mecánico de cubierta existente dañada y acopio | C14: m² | D14: 1625 | E14: =+$B$4 | F14: =D14*(1+E14) | G14: 7.8 | H14: =F14*G14
A15: 02.02 | B15: Desmontaje de chapas de petos exteriores, panel interior y rematería | C15: m² | D15: 662.4 | E15: =+$B$4 | F15: =D15*(1+E15) | G15: 6.5 | H15: =F15*G15
A16: 02.03 | B16: Bajada controlada de material a cota cero con grúa telescópica | C16: h | D16: 60 | E16: =+$B$4 | F16: =D16*(1+E16) | G16: 95 | H16: =F16*G16
A17: 02.04 | B17: Gestión integral de residuos contaminados: contenedores estancos, transporte y canon vertedero homologado | C17: m² | D17: 2287.4 | E17: =+$B$4 | F17: =D17*(1+E17) | G17: 8.8 | H17: =F17*G17
A18: SUBTOTAL CAPÍTULO 02: | H18: =SUM(H14:H17)
A20: CAPÍTULO 03 · SUMINISTRO E INSTALACIÓN DE NUEVA CUBIERTA Y LUCERNARIOS
A21: 03.01 | B21: Panel sándwich de cubierta 50 mm calidad marina exterior + blanco interior | C21: m² | D21: 1462.5 | E21: =+$B$4 | F21: =D21*(1+E21) | G21: 55 | H21: =F21*G21
A22: 03.02 | B22: Lucernarios de policarbonato celular grecado 30-40 mm UV (10%) | C22: m² | D22: 162.5 | E22: =+$B$4 | F22: =D22*(1+E22) | G22: 48 | H22: =F22*G22
A23: 03.03 | B23: Tornillería autotaladrante reforzada con arandela EPDM y caballetes | C23: Ud. | D23: 6250 | E23: =+$B$4 | F23: =D23*(1+E23) | G23: 0.38 | H23: =F23*G23
A24: 03.04 | B24: Mano de obra de colocación de panel sándwich y lucernarios | C24: m² | D24: 1625 | E24: =+$B$4 | F24: =D24*(1+E24) | G24: 65.3 | H24: =F24*G24
A25: SUBTOTAL CAPÍTULO 03: | H25: =SUM(H21:H24)
A27: CAPÍTULO 04 · PETOS PERIMETRALES (CHAPA HDX Y PANEL FACHADA) Y REMATERÍA
A28: 04.01 | B28: Chapa prelacada blanca Granite HDX 55 µm (C5-M) peto superior e inferior | C28: m² | D28: 441.6 | E28: =+$B$4 | F28: =D28*(1+E28) | G28: 38 | H28: =F28*G28
A29: 04.02 | B29: Panel sándwich de fachada 50 mm cara interior del peto | C29: m² | D29: 220.8 | E29: =+$B$4 | F29: =D29*(1+E29) | G29: 55 | H29: =F29*G29
A30: 04.03 | B30: Mano de obra montaje chapas HDX y panel fachada en petos | C30: m² | D30: 662.4 | E30: =+$B$4 | F30: =D30*(1+E30) | G30: 12.5 | H30: =F30*G30
A31: 04.04 | B31: Rematería conformada en chapa HDX: cumbrera, albardillas y baberos | C31: ml | D31: 438 | E31: =+$B$4 | F31: =D31*(1+E31) | G31: 16.5 | H31: =F31*G31
A32: 04.05 | B32: Mano de obra colocación rematería perimetral y sellados MS | C32: ml | D32: 438 | E32: =+$B$4 | F32: =D32*(1+E32) | G32: 8 | H32: =F32*G32
A33: SUBTOTAL CAPÍTULO 04: | H33: =SUM(H28:H32)
A35: CAPÍTULO 05 · CANALONES HDX, BAJANTES Y BABEROS DE ENTREGA
A36: 05.01 | B36: Canalón continuo conformado en chapa HDX (ambos aleros 140 ml + bajantes) | C36: ml | D36: 140 | E36: =+$B$4 | F36: =D36*(1+E36) | G36: 97.234286 | H36: =F36*G36
A37: SUBTOTAL CAPÍTULO 05: | H37: =SUM(H36:H36)
A39: CAPÍTULO 06 · SISTEMA DE LÍNEA DE VIDA LUX-TOP (EN 795-C)
A40: 06.01 | B40: Línea de vida continua LUX-TOP inox AISI 316 Ø8 mm cumbrera (70 ml base) | C40: ml | D40: 70 | E40: =+$B$4 | F40: =D40*(1+E40) | G40: 120 | H40: =F40*G40
A41: SUBTOTAL CAPÍTULO 06: | H41: =SUM(H40:H40)
A43: CAPÍTULO 07 · ESCALERA DE GATO INOX CON PROTECCIÓN DORSAL (12 ML)
A44: 07.01 | B44: Fabricación y suministro de escalera vertical de gato inox AISI 316 (12 m) | C44: ml | D44: 12 | E44: =+$B$4 | F44: =D44*(1+E44) | G44: 325 | H44: =F44*G44
A45: 07.02 | B45: Mano de obra de montaje, izado con plataforma y anclaje reforzado A4 | C45: ml | D45: 12 | E45: =+$B$4 | F45: =D45*(1+E45) | G45: 99.166667 | H45: =F45*G45
A46: SUBTOTAL CAPÍTULO 07: | H46: =SUM(H44:H45)
A48: CAPÍTULO 08 · MEDIOS AUXILIARES Y MAQUINARIA EN OBRA (3 MESES)
A49: 08.01 | B49: Plataformas elevadoras 4x4 homologadas AENA (3 meses), camión grúa y logística | C49: PA | D49: 1 | E49: 0 | F49: =D49*(1+E49) | G49: 21600 | H49: =F49*G49
...

Sheet Resumen Ejecutivo y KPIs
A1: RESUMEN EJECUTIVO Y CUADRO DE MANDO · CUBIERTA AENA
A2: Distribución de Costes por Capítulos, Ratios Económicos y Métricas Clave de Proyecto
A4: CÓDIGO | B4: CAPÍTULO / ALCANCE TÉCNICO | C4: IMPORTE (€) | D4: % SOBRE TOTAL | E4: RATIO €/M² CUBIERTA
A5: CAP. 01 | B5: Trabajos Previos, Seguridad y Tramitación AENA | C5: ='Presupuesto Oficial AENA'!F13 | D5: =C5/$C$13 | E5: =C5/1950
A6: CAP. 02 | B6: Desmontaje y Gestión Integral Residuos Contaminados | C6: ='Presupuesto Oficial AENA'!F20 | D6: =C6/$C$13 | E6: =C6/1950
A7: CAP. 03 | B7: Suministro e Instalación Cubierta y Lucernarios (1.950 m²) | C7: ='Presupuesto Oficial AENA'!F27 | D7: =C7/$C$13 | E7: =C7/1950
A8: CAP. 04 | B8: Petos Perimetrales (Chapa HDX + Panel Fachada) y Rematería | C8: ='Presupuesto Oficial AENA'!F35 | D8: =C8/$C$13 | E8: =C8/1950
A9: CAP. 05 | B9: Canalones HDX, Bajantes y Baberos de Entrega | C9: ='Presupuesto Oficial AENA'!F39 | D9: =C9/$C$13 | E9: =C9/1950
A10: CAP. 06 | B10: Sistema de Línea de Vida LUX-TOP inox AISI 316 (EN 795-C) | C10: ='Presupuesto Oficial AENA'!F43 | D10: =C10/$C$13 | E10: =C10/1950
A11: CAP. 07 | B11: Escalera de Gato Inox AISI 316 con Protección Dorsal (12 ml) | C11: ='Presupuesto Oficial AENA'!F48 | D11: =C11/$C$13 | E11: =C11/1950
A12: CAP. 08 | B12: Medios Auxiliares y Maquinaria en Obra (Plazo 3 Meses) | C12: ='Presupuesto Oficial AENA'!F52 | D12: =C12/$C$13 | E12: =C12/1950
A13: TOTAL BASE IMPONIBLE | C13: =SUM(C5:C12) | D13: =SUM(D5:D12) | E13: =C13/1950
A14: IVA Aplicable (21%) | C14: =C13*0.21
A15: TOTAL GENERAL PRESUPUESTO CON IVA | C15: =C13+C14
A17: MÉTRICAS Y KPIS PRINCIPALES
A18: Superficie Total Cubierta Presupuestada: | C18: 1.950,00 m²
A19: Ratio de Coste Total por m² de Cubierta: | C19: =C13/1950
A20: Plazo de Ejecución Estimado: | C20: 3 Meses (12 Semanas)
A21: Capítulo con Mayor Ponderación Económica: | C21: Cap. 03 (57,3%)
